Workbook

Sheet CLEANED DATASET
A1: PATIENT_ID | B1: AGE | C1: Gender | D1: GENDER2 | E1: Country_Region | F1: COUNTRY REGION | G1: Year | H1: Genetic_Risk | I1: GENETIC_RISK2 | J1: Air_Pollution | K1: AIR POLLUTION | L1: Alcohol_Use | M1: ALCOHOL USE | N1: Smoking | O1: SMOKING2 | P1: Obesity_Level | Q1: OBESITY LEVEL | R1: Cancer_Type | S1: Column1 | T1: Cancer_Stage | U1: Treatment_Cost_USD | V1: SURVIVAL_YEAR | W1: SURVIVAL YEAR | X1: TARGET_SEVERITY_SCORE | Y1: CANCER STAGE | Z1: TREATMENT COST USD
A2: PT0001777 | B2: 60 | C2: Male | D2: =PROPER(Table3[[#This Row],[Gender]]) -> Male | E2: Australia | F2: =PROPER(Table3[[#This Row],[Country_Region]]) -> Australia | G2: 2022 | H2: 6.1 | I2: =IF(H2="", AVERAGEIF('CLEANED DATASET'!$G$2:$G$532,G2,'CLEANED DATASET'!$H91),H2) -> 6.1 | J2: 2.1 | K2: =IF(J2="",ROUND(AVERAGEIF(G6:G532,G2,J2:J532),1),J2) -> 2.1 | L2: 6.3 | M2: =IF(L2="", AVERAGEIF(G2:G532, G2,L2:L532),L2) -> 6.3 | O2: =IF(N2="",AVERAGEIF(G2:G532,G2,N2:N532),N2) -> 4.6005848 | P2: 0.6 | Q2: =IF(P2="",AVERAGEIF(G2:G532,G2,P2:P532),P2) -> 0.6 | R2: Breast | S2: =PROPER(Table3[[#This Row],[Cancer_Type]]) -> Breast | T2: Stage II | U2: 35502.54 | V2: 7.4 | W2: =IF(Y2="Stage 0",RANDBETWEEN(9,10), IF(Y2="Stage I",RANDBETWEEN(7,8), IF(Y2="Stage II",RANDBETWEEN(5,6), IF(Y2="Stage III",RANDBETWEEN(3,4), IF(Y2="Stage IV",RANDBETWEEN(1,2),""))))) -> 7 | X2: 3.93 | Y2: =IF(X2<=2,"Stage 0",IF(X2<=4,"Stage I",IF(X2<=6,"Stage II",IF(X2<=8,"Stage III", "Stage IV")))) -> Stage I | Z2: =IF(U2<>"",U2,ROUND(AVERAGEIF(S2:S532,S2,U2:U532),2)) -> 35502.54
A3: PT0006143 | B3: 70 | C3: Male | D3: =PROPER(Table3[[#This Row],[Gender]]) -> Male | E3: RUSSIA | F3: =PROPER(Table3[[#This Row],[Country_Region]]) -> Russia | G3: 2023 | H3: 1.6 | I3: =IF(H3="", AVERAGEIF('CLEANED DATASET'!$G$2:$G$532,G3,'CLEANED DATASET'!$H201),H3) -> 1.6 | J3: 2 | K3: =IF(J3="",ROUND(AVERAGEIF(G7:G533,G3,J3:J533),1),J3) -> 2 | L3: 4.3 | M3: =IF(L3="", AVERAGEIF(G3:G533, G3,L3:L533),L3) -> 4.3 | N3: 5 | O3: =IF(N3="",AVERAGEIF(G3:G533,G3,N3:N533),N3) -> 5 | P3: 0.8 | Q3: =IF(P3="",AVERAGEIF(G3:G533,G3,P3:P533),P3) -> 0.8 | R3: Leukemia | S3: =PROPER(Table3[[#This Row],[Cancer_Type]]) -> Leukemia | T3: Stage I | U3: 16273.05 | V3: 1.5 | W3: =IF(Y3="Stage 0",RANDBETWEEN(9,10), IF(Y3="Stage I",RANDBETWEEN(7,8), IF(Y3="Stage II",RANDBETWEEN(5,6), IF(Y3="Stage III",RANDBETWEEN(3,4), IF(Y3="Stage IV",RANDBETWEEN(1,2),""))))) -> 6 | X3: 4.02 | Y3: =IF(X3<=2,"Stage 0",IF(X3<=4,"Stage I",IF(X3<=6,"Stage II",IF(X3<=8,"Stage III", "Stage IV")))) -> Stage II | Z3: =IF(U3<>"",U3,ROUND(AVERAGEIF(S3:S533,S3,U3:U533),2)) -> 16273.05
A4: PT0006792 | B4: 33 | C4: Other | D4: =PROPER(Table3[[#This Row],[Gender]]) -> Other | E4: BraZIL | F4: =PROPER(Table3[[#This Row],[Country_Region]]) -> Brazil | G4: 2024 | H4: 9.1 | I4: =IF(H4="", AVERAGEIF('CLEANED DATASET'!$G$2:$G$532,G4,'CLEANED DATASET'!$H125),H4) -> 9.1 | J4: 7.5 | K4: =IF(J4="",ROUND(AVERAGEIF(G8:G534,G4,J4:J534),1),J4) -> 7.5 | M4: =IF(L4="", AVERAGEIF(G4:G534, G4,L4:L534),L4) -> 4.712963 | N4: 7.5 | O4: =IF(N4="",AVERAGEIF(G4:G534,G4,N4:N534),N4) -> 7.5 | P4: 7 | Q4: =IF(P4="",AVERAGEIF(G4:G534,G4,P4:P534),P4) -> 7 | R4: Colon | S4: =PROPER(Table3[[#This Row],[Cancer_Type]]) -> Colon | T4: Stage III | U4: 22899.65 | V4: 7 | W4: =IF(Y4="Stage 0",RANDBETWEEN(9,10), IF(Y4="Stage I",RANDBETWEEN(7,8), IF(Y4="Stage II",RANDBETWEEN(5,6), IF(Y4="Stage III",RANDBETWEEN(3,4), IF(Y4="Stage IV",RANDBETWEEN(1,2),""))))) -> 4 | X4: 7.14 | Y4: =IF(X4<=2,"Stage 0",IF(X4<=4,"Stage I",IF(X4<=6,"Stage II",IF(X4<=8,"Stage III", "Stage IV")))) -> Stage III | Z4: =IF(U4<>"",U4,ROUND(AVERAGEIF(S4:S534,S4,U4:U534),2)) -> 22899.65
A5: PT0007169 | B5: 87 | C5: Female | D5: =PROPER(Table3[[#This Row],[Gender]]) -> Female | E5: Russia | F5: =PROPER(Table3[[#This Row],[Country_Region]]) -> Russia | G5: 2022 | H5: 7.5 | I5: =IF(H5="", AVERAGEIF('CLEANED DATASET'!$G$2:$G$532,G5,'CLEANED DATASET'!$H494),H5) -> 7.5 | J5: 8.5 | K5: =IF(J5="",ROUND(AVERAGEIF(G9:G535,G5,J5:J535),1),J5) -> 8.5 | L5: 0.9 | M5: =IF(L5="", AVERAGEIF(G5:G535, G5,L5:L535),L5) -> 0.9 | N5: 2.7 | O5: =IF(N5="",AVERAGEIF(G5:G535,G5,N5:N535),N5) -> 2.7 | P5: 8 | Q5: =IF(P5="",AVERAGEIF(G5:G535,G5,P5:P535),P5) -> 8 | R5: Skin | S5: =PROPER(Table3[[#This Row],[Cancer_Type]]) -> Skin | T5: Stage III | U5: 10195.07 | V5: 4 | W5: =IF(Y5="Stage 0",RANDBETWEEN(9,10), IF(Y5="Stage I",RANDBETWEEN(7,8), IF(Y5="Stage II",RANDBETWEEN(5,6), IF(Y5="Stage III",RANDBETWEEN(3,4), IF(Y5="Stage IV",RANDBETWEEN(1,2),""))))) -> 4 | X5: 6.05 | Y5: =IF(X5<=2,"Stage 0",IF(X5<=4,"Stage I",IF(X5<=6,"Stage II",IF(X5<=8,"Stage III", "Stage IV")))) -> Stage III | Z5: =IF(U5<>"",U5,ROUND(AVERAGEIF(S5:S535,S5,U5:U535),2)) -> 10195.07
A6: PT0007406 | B6: 56 | C6: Male | D6: =PROPER(Table3[[#This Row],[Gender]]) -> Male | E6: China | F6: =PROPER(Table3[[#This Row],[Country_Region]]) -> China | G6: 2022 | H6: 5.2 | I6: =IF(H6="", AVERAGEIF('CLEANED DATASET'!$G$2:$G$532,G6,'CLEANED DATASET'!$H392),H6) -> 5.2 | J6: 3.7 | K6: =IF(J6="",ROUND(AVERAGEIF(G10:G536,G6,J6:J536),1),J6) -> 3.7 | L6: 4.4 | M6: =IF(L6="", AVERAGEIF(G6:G536, G6,L6:L536),L6) -> 4.4 | N6: 3.8 | O6: =IF(N6="",AVERAGEIF(G6:G536,G6,N6:N536),N6) -> 3.8 | P6: 8.1 | Q6: =IF(P6="",AVERAGEIF(G6:G536,G6,P6:P536),P6) -> 8.1 | R6: Cervical | S6: =PROPER(Table3[[#This Row],[Cancer_Type]]) -> Cervical | T6: Stage I | U6: 8481.64 | V6: 2.2 | W6: =IF(Y6="Stage 0",RANDBETWEEN(9,10), IF(Y6="Stage I",RANDBETWEEN(7,8), IF(Y6="Stage II",RANDBETWEEN(5,6), IF(Y6="Stage III",RANDBETWEEN(3,4), IF(Y6="Stage IV",RANDBETWEEN(1,2),""))))) -> 6 | X6: 5.66 | Y6: =IF(X6<=2,"Stage 0",IF(X6<=4,"Stage I",IF(X6<=6,"Stage II",IF(X6<=8,"Stage III", "Stage IV")))) -> Stage II | Z6: =IF(U6<>"",U6,ROUND(AVERAGEIF(S6:S536,S6,U6:U536),2)) -> 8481.64
A7: PT0008067 | B7: 51 | C7: Male | D7: =PROPER(Table3[[#This Row],[Gender]]) -> Male | E7: Pakistan | F7: =PROPER(Table3[[#This Row],[Country_Region]]) -> Pakistan | G7: 2024 | H7: 0.6 | I7: =IF(H7="", AVERAGEIF('CLEANED DATASET'!$G$2:$G$532,G7,'CLEANED DATASET'!$H21),H7) -> 0.6 | J7: 9.7 | K7: =IF(J7="",ROUND(AVERAGEIF(G11:G537,G7,J7:J537),1),J7) -> 9.7 | L7: 0.8 | M7: =IF(L7="", AVERAGEIF(G7:G537, G7,L7:L537),L7) -> 0.8 | O7: =IF(N7="",AVERAGEIF(G7:G537,G7,N7:N537),N7) -> 5.0527607 | Q7: =IF(P7="",AVERAGEIF(G7:G537,G7,P7:P537),P7) -> 4.2546584 | R7: Leukemia | S7: =PROPER(Table3[[#This Row],[Cancer_Type]]) -> Leukemia | T7: Stage I | U7: 76197.01 | V7: 4.2 | W7: =IF(Y7="Stage 0",RANDBETWEEN(9,10), IF(Y7="Stage I",RANDBETWEEN(7,8), IF(Y7="Stage II",RANDBETWEEN(5,6), IF(Y7="Stage III",RANDBETWEEN(3,4), IF(Y7="Stage IV",RANDBETWEEN(1,2),""))))) -> 7 | X7: 3.16 | Y7: =IF(X7<=2,"Stage 0",IF(X7<=4,"Stage I",IF(X7<=6,"Stage II",IF(X7<=8,"Stage III", "Stage IV")))) -> Stage I | Z7: =IF(U7<>"",U7,ROUND(AVERAGEIF(S7:S537,S7,U7:U537),2)) -> 76197.01
A8: PT0008765 | B8: 29 | C8: Female | D8: =PROPER(Table3[[#This Row],[Gender]]) -> Female | E8: Pakistan | F8: =PROPER(Table3[[#This Row],[Country_Region]]) -> Pakistan | G8: 2022 | H8: 1 | I8: =IF(H8="", AVERAGEIF('CLEANED DATASET'!$G$2:$G$532,G8,'CLEANED DATASET'!$H522),H8) -> 1 | J8: 9.2 | K8: =IF(J8="",ROUND(AVERAGEIF(G12:G538,G8,J8:J538),1),J8) -> 9.2 | L8: 3.7 | M8: =IF(L8="", AVERAGEIF(G8:G538, G8,L8:L538),L8) -> 3.7 | N8: 3.4 | O8: =IF(N8="",AVERAGEIF(G8:G538,G8,N8:N538),N8) -> 3.4 | P8: 2.5 | Q8: =IF(P8="",AVERAGEIF(G8:G538,G8,P8:P538),P8) -> 2.5 | R8: Cervical | S8: =PROPER(Table3[[#This Row],[Cancer_Type]]) -> Cervical | T8: Stage II | V8: 6.3 | W8: =IF(Y8="Stage 0",RANDBETWEEN(9,10), IF(Y8="Stage I",RANDBETWEEN(7,8), IF(Y8="Stage II",RANDBETWEEN(5,6), IF(Y8="Stage III",RANDBETWEEN(3,4), IF(Y8="Stage IV",RANDBETWEEN(1,2),""))))) -> 6 | X8: 4.5 | Y8: =IF(X8<=2,"Stage 0",IF(X8<=4,"Stage I",IF(X8<=6,"Stage II",IF(X8<=8,"Stage III", "Stage IV")))) -> Stage II | Z8: 51711.04
A9: PT0008770 | B9: 73 | C9: Other | D9: =PROPER(Table3[[#This Row],[Gender]]) -> Other | E9: Brazil | F9: =PROPER(Table3[[#This Row],[Country_Region]]) -> Brazil | G9: 2023 | H9: 8.5 | I9: =IF(H9="", AVERAGEIF('CLEANED DATASET'!$G$2:$G$532,G9,'CLEANED DATASET'!$H268),H9) -> 8.5 | J9: 5.7 | K9: =IF(J9="",ROUND(AVERAGEIF(G13:G539,G9,J9:J539),1),J9) -> 5.7 | L9: 0.6 | M9: =IF(L9="", AVERAGEIF(G9:G539, G9,L9:L539),L9) -> 0.6 | N9: 4.3 | O9: =IF(N9="",AVERAGEIF(G9:G539,G9,N9:N539),N9) -> 4.3 | P9: 2.9 | Q9: =IF(P9="",AVERAGEIF(G9:G539,G9,P9:P539),P9) -> 2.9 | R9: Liver | S9: =PROPER(Table3[[#This Row],[Cancer_Type]]) -> Liver | T9: Stage I | U9: 60883.56 | V9: 10 | W9: =IF(Y9="Stage 0",RANDBETWEEN(9,10), IF(Y9="Stage I",RANDBETWEEN(7,8), IF(Y9="Stage II",RANDBETWEEN(5,6), IF(Y9="Stage III",RANDBETWEEN(3,4), IF(Y9="Stage IV",RANDBETWEEN(1,2),""))))) -> 5 | X9: 4.58 | Y9: =IF(X9<=2,"Stage 0",IF(X9<=4,"Stage I",IF(X9<=6,"Stage II",IF(X9<=8,"Stage III", "Stage IV")))) -> Stage II | Z9: =IF(U9<>"",U9,ROUND(AVERAGEIF(S9:S539,S9,U9:U539),2)) -> 60883.56
A10: PT0008867 | B10: 29 | C10: Unknown | D10: =PROPER(Table3[[#This Row],[Gender]]) -> Unknown | E10: Canada | F10: =PROPER(Table3[[#This Row],[Country_Region]]) -> Canada | G10: 2024 | I10: =IF(H10="", AVERAGEIF('CLEANED DATASET'!$G$2:$G$532,G10,'CLEANED DATASET'!$H485),H10) -> 4.0736842 | J10: 3.5 | K10: =IF(J10="",ROUND(AVERAGEIF(G14:G540,G10,J10:J540),1),J10) -> 3.5 | L10: 7.1 | M10: =IF(L10="", AVERAGEIF(G10:G540, G10,L10:L540),L10) -> 7.1 | N10: 2.2 | O10: =IF(N10="",AVERAGEIF(G10:G540,G10,N10:N540),N10) -> 2.2 | P10: 3.6 | Q10: =IF(P10="",AVERAGEIF(G10:G540,G10,P10:P540),P10) -> 3.6 | R10: Prostate | S10: =PROPER(Table3[[#This Row],[Cancer_Type]]) -> Prostate | T10: Stage 0 | U10: 94485.75 | V10: 1.8 | W10: =IF(Y10="Stage 0",RANDBETWEEN(9,10), IF(Y10="Stage I",RANDBETWEEN(7,8), IF(Y10="Stage II",RANDBETWEEN(5,6), IF(Y10="Stage III",RANDBETWEEN(3,4), IF(Y10="Stage IV",RANDBETWEEN(1,2),""))))) -> 8 | X10: 3.3 | Y10: =IF(X10<=2,"Stage 0",IF(X10<=4,"Stage I",IF(X10<=6,"Stage II",IF(X10<=8,"Stage III", "Stage IV")))) -> Stage I | Z10: =IF(U10<>"",U10,ROUND(AVERAGEIF(S10:S540,S10,U10:U540),2)) -> 94485.75
A11: PT0009237 | B11: 33 | C11: Female | D11: =PROPER(Table3[[#This Row],[Gender]]) -> Female | E11: Pakistan | F11: =PROPER(Table3[[#This Row],[Country_Region]]) -> Pakistan | G11: 2023 | H11: 7.7 | I11: =IF(H11="", AVERAGEIF('CLEANED DATASET'!$G$2:$G$532,G11,'CLEANED DATASET'!$H160),H11) -> 7.7 | J11: 4.5 | K11: =IF(J11="",ROUND(AVERAGEIF(G15:G541,G11,J11:J541),1),J11) -> 4.5 | L11: 2.4 | M11: =IF(L11="", AVERAGEIF(G11:G541, G11,L11:L541),L11) -> 2.4 | N11: 2.3 | O11: =IF(N11="",AVERAGEIF(G11:G541,G11,N11:N541),N11) -> 2.3 | P11: 5.2 | Q11: =IF(P11="",AVERAGEIF(G11:G541,G11,P11:P541),P11) -> 5.2 | R11: Colon | S11: =PROPER(Table3[[#This Row],[Cancer_Type]]) -> Colon | T11: Stage III | U11: 43439 | V11: 4.1 | W11: =IF(Y11="Stage 0",RANDBETWEEN(9,10), IF(Y11="Stage I",RANDBETWEEN(7,8), IF(Y11="Stage II",RANDBETWEEN(5,6), IF(Y11="Stage III",RANDBETWEEN(3,4), IF(Y11="Stage IV",RANDBETWEEN(1,2),""))))) -> 6 | X11: 4.69 | Y11: =IF(X11<=2,"Stage 0",IF(X11<=4,"Stage I",IF(X11<=6,"Stage II",IF(X11<=8,"Stage III", "Stage IV")))) -> Stage II | Z11: =IF(U11<>"",U11,ROUND(AVERAGEIF(S11:S541,S11,U11:U541),2)) -> 43439
A12: PT0009519 | B12: 23 | C12: Other | D12: =PROPER(Table3[[#This Row],[Gender]]) -> Other | E12: indIA | F12: =PROPER(Table3[[#This Row],[Country_Region]]) -> India | G12: 2024 | H12: 1.6 | I12: =IF(H12="", AVERAGEIF('CLEANED DATASET'!$G$2:$G$532,G12,'CLEANED DATASET'!$H294),H12) -> 1.6 | J12: 0.5 | K12: =IF(J12="",ROUND(AVERAGEIF(G16:G542,G12,J12:J542),1),J12) -> 0.5 | L12: 3.5 | M12: =IF(L12="", AVERAGEIF(G12:G542, G12,L12:L542),L12) -> 3.5 | N12: 4.6 | O12: =IF(N12="",AVERAGEIF(G12:G542,G12,N12:N542),N12) -> 4.6 | P12: 7.8 | Q12: =IF(P12="",AVERAGEIF(G12:G542,G12,P12:P542),P12) -> 7.8 | R12: Leukemia | S12: =PROPER(Table3[[#This Row],[Cancer_Type]]) -> Leukemia | T12: Stage I | U12: 66140.43 | V12: 6.8 | W12: =IF(Y12="Stage 0",RANDBETWEEN(9,10), IF(Y12="Stage I",RANDBETWEEN(7,8), IF(Y12="Stage II",RANDBETWEEN(5,6), IF(Y12="Stage III",RANDBETWEEN(3,4), IF(Y12="Stage IV",RANDBETWEEN(1,2),""))))) -> 8 | X12: 3.3 | Y12: =IF(X12<=2,"Stage 0",IF(X12<=4,"Stage I",IF(X12<=6,"Stage II",IF(X12<=8,"Stage III", "Stage IV")))) -> Stage I | Z12: =IF(U12<>"",U12,ROUND(AVERAGEIF(S12:S542,S12,U12:U542),2)) -> 66140.43
A13: PT0009578 | B13: 47 | C13: Male | D13: =PROPER(Table3[[#This Row],[Gender]]) -> Male | E13: USA | F13: =PROPER(Table3[[#This Row],[Country_Region]]) -> Usa | G13: 2024 | H13: 7.7 | I13: =IF(H13="", AVERAGEIF('CLEANED DATASET'!$G$2:$G$532,G13,'CLEANED DATASET'!$H526),H13) -> 7.7 | J13: 0.9 | K13: =IF(J13="",ROUND(AVERAGEIF(G17:G543,G13,J13:J543),1),J13) -> 0.9 | L13: 3 | M13: =IF(L13="", AVERAGEIF(G13:G543, G13,L13:L543),L13) -> 3 | N13: 6.5 | O13: =IF(N13="",AVERAGEIF(G13:G543,G13,N13:N543),N13) -> 6.5 | P13: 5.9 | Q13: =IF(P13="",AVERAGEIF(G13:G543,G13,P13:P543),P13) -> 5.9 | R13: Leukemia | S13: =PROPER(Table3[[#This Row],[Cancer_Type]]) -> Leukemia | T13: Stage IV | U13: 51804.21 | V13: 3.8 | W13: =IF(Y13="Stage 0",RANDBETWEEN(9,10), IF(Y13="Stage I",RANDBETWEEN(7,8), IF(Y13="Stage II",RANDBETWEEN(5,6), IF(Y13="Stage III",RANDBETWEEN(3,4), IF(Y13="Stage IV",RANDBETWEEN(1,2),""))))) -> 6 | X13: 4.98 | Y13: =IF(X13<=2,"Stage 0",IF(X13<=4,"Stage I",IF(X13<=6,"Stage II",IF(X13<=8,"Stage III", "Stage IV")))) -> Stage II | Z13: =IF(U13<>"",U13,ROUND(AVERAGEIF(S13:S543,S13,U13:U543),2)) -> 51804.21
A14: PT0009724 | B14: 48 | C14: Male | D14: =PROPER(Table3[[#This Row],[Gender]]) -> Male | E14: Australia | F14: =PROPER(Table3[[#This Row],[Country_Region]]) -> Australia | G14: 2022 | H14: 4.5 | I14: =IF(H14="", AVERAGEIF('CLEANED DATASET'!$G$2:$G$532,G14,'CLEANED DATASET'!$H387),H14) -> 4.5 | J14: 8.3 | K14: =IF(J14="",ROUND(AVERAGEIF(G18:G544,G14,J14:J544),1),J14) -> 8.3 | L14: 5.9 | M14: =IF(L14="", AVERAGEIF(G14:G544, G14,L14:L544),L14) -> 5.9 | N14: 2.1 | O14: =IF(N14="",AVERAGEIF(G14:G544,G14,N14:N544),N14) -> 2.1 | P14: 7 | Q14: =IF(P14="",AVERAGEIF(G14:G544,G14,P14:P544),P14) -> 7 | R14: Leukemia | S14: =PROPER(Table3[[#This Row],[Cancer_Type]]) -> Leukemia | T14: Stage I | U14: 67604.88 | V14: 0.3 | W14: =IF(Y14="Stage 0",RANDBETWEEN(9,10), IF(Y14="Stage I",RANDBETWEEN(7,8), IF(Y14="Stage II",RANDBETWEEN(5,6), IF(Y14="Stage III",RANDBETWEEN(3,4), IF(Y14="Stage IV",RANDBETWEEN(1,2),""))))) -> 5 | X14: 4.8 | Y14: =IF(X14<=2,"Stage 0",IF(X14<=4,"Stage I",IF(X14<=6,"Stage II",IF(X14<=8,"Stage III", "Stage IV")))) -> Stage II | Z14: =IF(U14<>"",U14,ROUND(AVERAGEIF(S14:S544,S14,U14:U544),2)) -> 67604.88
A15: PT0009788 | B15: 82 | C15: Male | D15: =PROPER(Table3[[#This Row],[Gender]]) -> Male | E15: Brazil | F15: =PROPER(Table3[[#This Row],[Country_Region]]) -> Brazil | G15: 2024 | H15: 6.3 | I15: =IF(H15="", AVERAGEIF('CLEANED DATASET'!$G$2:$G$532,G15,'CLEANED DATASET'!$H507),H15) -> 6.3 | J15: 6.4 | K15: =IF(J15="",ROUND(AVERAGEIF(G19:G545,G15,J15:J545),1),J15) -> 6.4 | L15: 3.8 | M15: =IF(L15="", AVERAGEIF(G15:G545, G15,L15:L545),L15) -> 3.8 | N15: 8.2 | O15: =IF(N15="",AVERAGEIF(G15:G545,G15,N15:N545),N15) -> 8.2 | P15: 2.1 | Q15: =IF(P15="",AVERAGEIF(G15:G545,G15,P15:P545),P15) -> 2.1 | R15: Colon | S15: =PROPER(Table3[[#This Row],[Cancer_Type]]) -> Colon | T15: Stage 0 | U15: 23446.24 | V15: 8.2 | W15: =IF(Y15="Stage 0",RANDBETWEEN(9,10), IF(Y15="Stage I",RANDBETWEEN(7,8), IF(Y15="Stage II",RANDBETWEEN(5,6), IF(Y15="Stage III",RANDBETWEEN(3,4), IF(Y15="Stage IV",RANDBETWEEN(1,2),""))))) -> 4 | X15: 6.17 | Y15: =IF(X15<=2,"Stage 0",IF(X15<=4,"Stage I",IF(X15<=6,"Stage II",IF(X15<=8,"Stage III", "Stage IV")))) -> Stage III | Z15: =IF(U15<>"",U15,ROUND(AVERAGEIF(S15:S545,S15,U15:U545),2)) -> 23446.24
A16: PT0009894 | B16: 39 | C16: Unknown | D16: =PROPER(Table3[[#This Row],[Gender]]) -> Unknown | E16: China | F16: =PROPER(Table3[[#This Row],[Country_Region]]) -> China | G16: 2022 | H16: 8.5 | I16: =IF(H16="", AVERAGEIF('CLEANED DATASET'!$G$2:$G$532,G16,'CLEANED DATASET'!$H463),H16) -> 8.5 | J16: 2.7 | K16: =IF(J16="",ROUND(AVERAGEIF(G20:G546,G16,J16:J546),1),J16) -> 2.7 | L16: 6.6 | M16: =IF(L16="", AVERAGEIF(G16:G546, G16,L16:L546),L16) -> 6.6 | N16: 7.6 | O16: =IF(N16="",AVERAGEIF(G16:G546,G16,N16:N546),N16) -> 7.6 | P16: 8.8 | Q16: =IF(P16="",AVERAGEIF(G16:G546,G16,P16:P546),P16) -> 8.8 | R16: Lung | S16: =PROPER(Table3[[#This Row],[Cancer_Type]]) -> Lung | U16: 73059.18 | V16: 5.3 | W16: =IF(Y16="Stage 0",RANDBETWEEN(9,10), IF(Y16="Stage I",RANDBETWEEN(7,8), IF(Y16="Stage II",RANDBETWEEN(5,6), IF(Y16="Stage III",RANDBETWEEN(3,4), IF(Y16="Stage IV",RANDBETWEEN(1,2),""))))) -> 3 | X16: 6.03 | Y16: =IF(X16<=2,"Stage 0",IF(X16<=4,"Stage I",IF(X16<=6,"Stage II",IF(X16<=8,"Stage III", "Stage IV")))) -> Stage III | Z16: =IF(U16<>"",U16,ROUND(AVERAGEIF(S16:S546,S16,U16:U546),2)) -> 73059.18
A17: PT0009964 | B17: 76 | C17: Male | D17: =PROPER(Table3[[#This Row],[Gender]]) -> Male | E17: Pakistan | F17: =PROPER(Table3[[#This Row],[Country_Region]]) -> Pakistan | G17: 2024 | H17: 0.7 | I17: =IF(H17="", AVERAGEIF('CLEANED DATASET'!$G$2:$G$532,G17,'CLEANED DATASET'!$H404),H17) -> 0.7 | J17: 5.5 | K17: =IF(J17="",ROUND(AVERAGEIF(G21:G547,G17,J17:J547),1),J17) -> 5.5 | L17: 7.7 | M17: =IF(L17="", AVERAGEIF(G17:G547, G17,L17:L547),L17) -> 7.7 | N17: 8.1 | O17: =IF(N17="",AVERAGEIF(G17:G547,G17,N17:N547),N17) -> 8.1 | P17: 1.3 | Q17: =IF(P17="",AVERAGEIF(G17:G547,G17,P17:P547),P17) -> 1.3 | R17: Colon | S17: =PROPER(Table3[[#This Row],[Cancer_Type]]) -> Colon | T17: Stage IV | U17: 38236.05 | V17: 4 | W17: =IF(Y17="Stage 0",RANDBETWEEN(9,10), IF(Y17="Stage I",RANDBETWEEN(7,8), IF(Y17="Stage II",RANDBETWEEN(5,6), IF(Y17="Stage III",RANDBETWEEN(3,4), IF(Y17="Stage IV",RANDBETWEEN(1,2),""))))) -> 6 | X17: 5.11 | Y17: =IF(X17<=2,"Stage 0",IF(X17<=4,"Stage I",IF(X17<=6,"Stage II",IF(X17<=8,"Stage III", "Stage IV")))) -> Stage II | Z17: =IF(U17<>"",U17,ROUND(AVERAGEIF(S17:S547,S17,U17:U547),2)) -> 38236.05
A18: PT0010069 | B18: 84 | C18: Female | D18: =PROPER(Table3[[#This Row],[Gender]]) -> Female | E18: Brazil | F18: =PROPER(Table3[[#This Row],[Country_Region]]) -> Brazil | G18: 2022 | H18: 8.4 | I18: =IF(H18="", AVERAGEIF('CLEANED DATASET'!$G$2:$G$532,G18,'CLEANED DATASET'!$H61),H18) -> 8.4 | J18: 6.3 | K18: =IF(J18="",ROUND(AVERAGEIF(G22:G548,G18,J18:J548),1),J18) -> 6.3 | L18: 1.9 | M18: =IF(L18="", AVERAGEIF(G18:G548, G18,L18:L548),L18) -> 1.9 | N18: 1.9 | O18: =IF(N18="",AVERAGEIF(G18:G548,G18,N18:N548),N18) -> 1.9 | P18: 8.5 | Q18: =IF(P18="",AVERAGEIF(G18:G548,G18,P18:P548),P18) -> 8.5 | R18: UnKnoWn | S18: =PROPER(Table3[[#This Row],[Cancer_Type]]) -> Unknown | T18: Stage II | U18: 78070.97 | V18: 3.1 | W18: =IF(Y18="Stage 0",RANDBETWEEN(9,10), IF(Y18="Stage I",RANDBETWEEN(7,8), IF(Y18="Stage II",RANDBETWEEN(5,6), IF(Y18="Stage III",RANDBETWEEN(3,4), IF(Y18="Stage IV",RANDBETWEEN(1,2),""))))) -> 6 | X18: 4.58 | Y18: =IF(X18<=2,"Stage 0",IF(X18<=4,"Stage I",IF(X18<=6,"Stage II",IF(X18<=8,"Stage III", "Stage IV")))) -> Stage II | Z18: =IF(U18<>"",U18,ROUND(AVERAGEIF(S18:S548,S18,U18:U548),2)) -> 78070.97
A19: PT0010207 | B19: 45 | C19: Male | D19: =PROPER(Table3[[#This Row],[Gender]]) -> Male | E19: Germany | F19: =PROPER(Table3[[#This Row],[Country_Region]]) -> Germany | G19: 2024 | H19: 6 | I19: =IF(H19="", AVERAGEIF('CLEANED DATASET'!$G$2:$G$532,G19,'CLEANED DATASET'!$H112),H19) -> 6 | J19: 5.7 | K19: =IF(J19="",ROUND(AVERAGEIF(G23:G549,G19,J19:J549),1),J19) -> 5.7 | L19: 3.2 | M19: =IF(L19="", AVERAGEIF(G19:G549, G19,L19:L549),L19) -> 3.2 | N19: 1.2 | O19: =IF(N19="",AVERAGEIF(G19:G549,G19,N19:N549),N19) -> 1.2 | P19: 6.3 | Q19: =IF(P19="",AVERAGEIF(G19:G549,G19,P19:P549),P19) -> 6.3 | R19: Lung | S19: =PROPER(Table3[[#This Row],[Cancer_Type]]) -> Lung | U19: 89146.62 | V19: 6.1 | W19: =IF(Y19="Stage 0",RANDBETWEEN(9,10), IF(Y19="Stage I",RANDBETWEEN(7,8), IF(Y19="Stage II",RANDBETWEEN(5,6), IF(Y19="Stage III",RANDBETWEEN(3,4), IF(Y19="Stage IV",RANDBETWEEN(1,2),""))))) -> 8 | X19: 3.62 | Y19: =IF(X19<=2,"Stage 0",IF(X19<=4,"Stage I",IF(X19<=6,"Stage II",IF(X19<=8,"Stage III", "Stage IV")))) -> Stage I | Z19: =IF(U19<>"",U19,ROUND(AVERAGEIF(S19:S549,S19,U19:U549),2)) -> 89146.62
A20: PT0010331 | B20: 35 | C20: Unknown | D20: =PROPER(Table3[[#This Row],[Gender]]) -> Unknown | E20: Brazil | F20: =PROPER(Table3[[#This Row],[Country_Region]]) -> Brazil | G20: 2023 | H20: 3.3 | I20: =IF(H20="", AVERAGEIF('CLEANED DATASET'!$G$2:$G$532,G20,'CLEANED DATASET'!$H325),H20) -> 3.3 | J20: 6.1 | K20: =IF(J20="",ROUND(AVERAGEIF(G24:G550,G20,J20:J550),1),J20) -> 6.1 | L20: 0.8 | M20: =IF(L20="", AVERAGEIF(G20:G550, G20,L20:L550),L20) -> 0.8 | N20: 0.4 | O20: =IF(N20="",AVERAGEIF(G20:G550,G20,N20:N550),N20) -> 0.4 | P20: 9.8 | Q20: =IF(P20="",AVERAGEIF(G20:G550,G20,P20:P550),P20) -> 9.8 | R20: unknown | S20: =PROPER(Table3[[#This Row],[Cancer_Type]]) -> Unknown | U20: 15035.87 | V20: 4.2 | W20: =IF(Y20="Stage 0",RANDBETWEEN(9,10), IF(Y20="Stage I",RANDBETWEEN(7,8), IF(Y20="Stage II",RANDBETWEEN(5,6), IF(Y20="Stage III",RANDBETWEEN(3,4), IF(Y20="Stage IV",RANDBETWEEN(1,2),""))))) -> 6 | X20: 4.45 | Y20: =IF(X20<=2,"Stage 0",IF(X20<=4,"Stage I",IF(X20<=6,"Stage II",IF(X20<=8,"Stage III", "Stage IV")))) -> Stage II | Z20: =IF(U20<>"",U20,ROUND(AVERAGEIF(S20:S550,S20,U20:U550),2)) -> 15035.87
A21: PT0010397 | B21: 41 | C21: Female | D21: =PROPER(Table3[[#This Row],[Gender]]) -> Female | E21: Germany | F21: =PROPER(Table3[[#This Row],[Country_Region]]) -> Germany | G21: 2022 | H21: 7.7 | I21: =IF(H21="", AVERAGEIF('CLEANED DATASET'!$G$2:$G$532,G21,'CLEANED DATASET'!$H109),H21) -> 7.7 | J21: 8.5 | K21: =IF(J21="",ROUND(AVERAGEIF(G25:G551,G21,J21:J551),1),J21) -> 8.5 | L21: 8.2 | M21: =IF(L21="", AVERAGEIF(G21:G551, G21,L21:L551),L21) -> 8.2 | N21: 5.4 | O21: =IF(N21="",AVERAGEIF(G21:G551,G21,N21:N551),N21) -> 5.4 | P21: 7.6 | Q21: =IF(P21="",AVERAGEIF(G21:G551,G21,P21:P551),P21) -> 7.6 | R21: Colon | S21: =PROPER(Table3[[#This Row],[Cancer_Type]]) -> Colon | U21: 95857.65 | V21: =ROUND(10-((I21+K21+M21+O21+Q21)/5),1) -> 2.5 | W21: =IF(Y21="Stage 0",RANDBETWEEN(9,10), IF(Y21="Stage I",RANDBETWEEN(7,8), IF(Y21="Stage II",RANDBETWEEN(5,6), IF(Y21="Stage III",RANDBETWEEN(3,4), IF(Y21="Stage IV",RANDBETWEEN(1,2),""))))) -> 5 | X21: 5.97 | Y21: =IF(X21<=2,"Stage 0",IF(X21<=4,"Stage I",IF(X21<=6,"Stage II",IF(X21<=8,"Stage III", "Stage IV")))) -> Stage II | Z21: =IF(U21<>"",U21,ROUND(AVERAGEIF(S21:S551,S21,U21:U551),2)) -> 95857.65
A22: PT0010482 | B22: 24 | C22: Male | D22: =PROPER(Table3[[#This Row],[Gender]]) -> Male | E22: Canada | F22: =PROPER(Table3[[#This Row],[Country_Region]]) -> Canada | G22: 2024 | H22: 6.7 | I22: =IF(H22="", AVERAGEIF('CLEANED DATASET'!$G$2:$G$532,G22,'CLEANED DATASET'!$H10),H22) -> 6.7 | J22: 6.2 | K22: =IF(J22="",ROUND(AVERAGEIF(G26:G552,G22,J22:J552),1),J22) -> 6.2 | L22: 0.5 | M22: =IF(L22="", AVERAGEIF(G22:G552, G22,L22:L552),L22) -> 0.5 | N22: 3.9 | O22: =IF(N22="",AVERAGEIF(G22:G552,G22,N22:N552),N22) -> 3.9 | P22: 9.4 | Q22: =IF(P22="",AVERAGEIF(G22:G552,G22,P22:P552),P22) -> 9.4 | R22: Breast | S22: =PROPER(Table3[[#This Row],[Cancer_Type]]) -> Breast | T22: Stage II | U22: 23864.53 | V22: 6.2 | W22: =IF(Y22="Stage 0",RANDBETWEEN(9,10), IF(Y22="Stage I",RANDBETWEEN(7,8), IF(Y22="Stage II",RANDBETWEEN(5,6), IF(Y22="Stage III",RANDBETWEEN(3,4), IF(Y22="Stage IV",RANDBETWEEN(1,2),""))))) -> 6 | X22: 5.59 | Y22: =IF(X22<=2,"Stage 0",IF(X22<=4,"Stage I",IF(X22<=6,"Stage II",IF(X22<=8,"Stage III", "Stage IV")))) -> Stage II | Z22: =IF(U22<>"",U22,ROUND(AVERAGEIF(S22:S552,S22,U22:U552),2)) -> 23864.53
A23: PT0010560 | B23: 22 | C23: Male | D23: =PROPER(Table3[[#This Row],[Gender]]) -> Male | E23: India | F23: =PROPER(Table3[[#This Row],[Country_Region]]) -> India | G23: 2023 | H23: 4.2 | I23: =IF(H23="", AVERAGEIF('CLEANED DATASET'!$G$2:$G$532,G23,'CLEANED DATASET'!$H16),H23) -> 4.2 | J23: 0.1 | K23: =IF(J23="",ROUND(AVERAGEIF(G27:G553,G23,J23:J553),1),J23) -> 0.1 | L23: 6.9 | M23: =IF(L23="", AVERAGEIF(G23:G553, G23,L23:L553),L23) -> 6.9 | N23: 7.9 | O23: =IF(N23="",AVERAGEIF(G23:G553,G23,N23:N553),N23) -> 7.9 | P23: 0.9 | Q23: =IF(P23="",AVERAGEIF(G23:G553,G23,P23:P553),P23) -> 0.9 | R23: Unknown | S23: =PROPER(Table3[[#This Row],[Cancer_Type]]) -> Unknown | T23: Stage IV | U23: 66182.17 | V23: 9 | W23: =IF(Y23="Stage 0",RANDBETWEEN(9,10), IF(Y23="Stage I",RANDBETWEEN(7,8), IF(Y23="Stage II",RANDBETWEEN(5,6), IF(Y23="Stage III",RANDBETWEEN(3,4), IF(Y23="Stage IV",RANDBETWEEN(1,2),""))))) -> 5 | X23: 4.24 | Y23: =IF(X23<=2,"Stage 0",IF(X23<=4,"Stage I",IF(X23<=6,"Stage II",IF(X23<=8,"Stage III", "Stage IV")))) -> Stage II | Z23: =IF(U23<>"",U23,ROUND(AVERAGEIF(S23:S553,S23,U23:U553),2)) -> 66182.17
A24: PT0010634 | B24: 54 | C24: Unknown | D24: =PROPER(Table3[[#This Row],[Gender]]) -> Unknown | E24: canada | F24: =PROPER(Table3[[#This Row],[Country_Region]]) -> Canada | G24: 2023 | H24: 3.5 | I24: =IF(H24="", AVERAGEIF('CLEANED DATASET'!$G$2:$G$532,G24,'CLEANED DATASET'!$H183),H24) -> 3.5 | J24: 5.2 | K24: =IF(J24="",ROUND(AVERAGEIF(G28:G554,G24,J24:J554),1),J24) -> 5.2 | L24: 9.5 | M24: =IF(L24="", AVERAGEIF(G24:G554, G24,L24:L554),L24) -> 9.5 | N24: 5.2 | O24: =IF(N24="",AVERAGEIF(G24:G554,G24,N24:N554),N24) -> 5.2 | P24: 9.1 | Q24: =IF(P24="",AVERAGEIF(G24:G554,G24,P24:P554),P24) -> 9.1 | R24: UNKNOWN | S24: =PROPER(Table3[[#This Row],[Cancer_Type]]) -> Unknown | T24: Stage I | U24: 98864.58 | V24: 7.4 | W24: =IF(Y24="Stage 0",RANDBETWEEN(9,10), IF(Y24="Stage I",RANDBETWEEN(7,8), IF(Y24="Stage II",RANDBETWEEN(5,6), IF(Y24="Stage III",RANDBETWEEN(3,4), IF(Y24="Stage IV",RANDBETWEEN(1,2),""))))) -> 5 | X24: 4.88 | Y24: =IF(X24<=2,"Stage 0",IF(X24<=4,"Stage I",IF(X24<=6,"Stage II",IF(X24<=8,"Stage III", "Stage IV")))) -> Stage II | Z24: =IF(U24<>"",U24,ROUND(AVERAGEIF(S24:S554,S24,U24:U554),2)) -> 98864.58
A25: PT0010748 | B25: 79 | C25: Other | D25: =PROPER(Table3[[#This Row],[Gender]]) -> Other | E25: Pakistan | F25: =PROPER(Table3[[#This Row],[Country_Region]]) -> Pakistan | G25: 2022 | H25: 1.2 | I25: =IF(H25="", AVERAGEIF('CLEANED DATASET'!$G$2:$G$532,G25,'CLEANED DATASET'!$H258),H25) -> 1.2 | J25: 0.8 | K25: =IF(J25="",ROUND(AVERAGEIF(G29:G555,G25,J25:J555),1),J25) -> 0.8 | M25: =IF(L25="", AVERAGEIF(G25:G555, G25,L25:L555),L25) -> 4.8648148 | N25: 3.4 | O25: =IF(N25="",AVERAGEIF(G25:G555,G25,N25:N555),N25) -> 3.4 | P25: 0.9 | Q25: =IF(P25="",AVERAGEIF(G25:G555,G25,P25:P555),P25) -> 0.9 | R25: Leukemia | S25: =PROPER(Table3[[#This Row],[Cancer_Type]]) -> Leukemia | T25: Stage III | U25: 69802.05 | V25: 6.6 | W25: =IF(Y25="Stage 0",RANDBETWEEN(9,10), IF(Y25="Stage I",RANDBETWEEN(7,8), IF(Y25="Stage II",RANDBETWEEN(5,6), IF(Y25="Stage III",RANDBETWEEN(3,4), IF(Y25="Stage IV",RANDBETWEEN(1,2),""))))) -> 7 | X25: 2.36 | Y25: =IF(X25<=2,"Stage 0",IF(X25<=4,"Stage I",IF(X25<=6,"Stage II",IF(X25<=8,"Stage III", "Stage IV")))) -> Stage I | Z25: =IF(U25<>"",U25,ROUND(AVERAGEIF(S25:S555,S25,U25:U555),2)) -> 69802.05
A26: PT0010771 | B26: 38 | C26: Male | D26: =PROPER(Table3[[#This Row],[Gender]]) -> Male | E26: Canada | F26: =PROPER(Table3[[#This Row],[Country_Region]]) -> Canada | G26: 2022 | H26: 6.2 | I26: =IF(H26="", AVERAGEIF('CLEANED DATASET'!$G$2:$G$532,G26,'CLEANED DATASET'!$H135),H26) -> 6.2 | J26: 5.7 | K26: =IF(J26="",ROUND(AVERAGEIF(G30:G556,G26,J26:J556),1),J26) -> 5.7 | L26: 6.4 | M26: =IF(L26="", AVERAGEIF(G26:G556, G26,L26:L556),L26) -> 6.4 | O26: =IF(N26="",AVERAGEIF(G26:G556,G26,N26:N556),N26) -> 4.6404908 | P26: 3.4 | Q26: =IF(P26="",AVERAGEIF(G26:G556,G26,P26:P556),P26) -> 3.4 | R26: Breast | S26: =PROPER(Table3[[#This Row],[Cancer_Type]]) -> Breast | T26: Stage 0 | U26: 59531.44 | V26: 6.5 | W26: =IF(Y26="Stage 0",RANDBETWEEN(9,10), IF(Y26="Stage I",RANDBETWEEN(7,8), IF(Y26="Stage II",RANDBETWEEN(5,6), IF(Y26="Stage III",RANDBETWEEN(3,4), IF(Y26="Stage IV",RANDBETWEEN(1,2),""))))) -> 5 | X26: 5.04 | Y26: =IF(X26<=2,"Stage 0",IF(X26<=4,"Stage I",IF(X26<=6,"Stage II",IF(X26<=8,"Stage III", "Stage IV")))) -> Stage II | Z26: =IF(U26<>"",U26,ROUND(AVERAGEIF(S26:S556,S26,U26:U556),2)) -> 59531.44
A27: PT0010867 | B27: 41 | C27: Unknown | D27: =PROPER(Table3[[#This Row],[Gender]]) -> Unknown | E27: Germany | F27: =PROPER(Table3[[#This Row],[Country_Region]]) -> Germany | G27: 2023 | H27: 0.7 | I27: =IF(H27="", AVERAGEIF('CLEANED DATASET'!$G$2:$G$532,G27,'CLEANED DATASET'!$H129),H27) -> 0.7 | J27: 4.4 | K27: =IF(J27="",ROUND(AVERAGEIF(G31:G557,G27,J27:J557),1),J27) -> 4.4 | L27: 7.1 | M27: =IF(L27="", AVERAGEIF(G27:G557, G27,L27:L557),L27) -> 7.1 | N27: 2 | O27: =IF(N27="",AVERAGEIF(G27:G557,G27,N27:N557),N27) -> 2 | P27: 2.6 | Q27: =IF(P27="",AVERAGEIF(G27:G557,G27,P27:P557),P27) -> 2.6 | R27: Cervical | S27: =PROPER(Table3[[#This Row],[Cancer_Type]]) -> Cervical | T27: Stage II | U27: 60800.41 | V27: 9.7 | W27: =IF(Y27="Stage 0",RANDBETWEEN(9,10), IF(Y27="Stage I",RANDBETWEEN(7,8), IF(Y27="Stage II",RANDBETWEEN(5,6), IF(Y27="Stage III",RANDBETWEEN(3,4), IF(Y27="Stage IV",RANDBETWEEN(1,2),""))))) -> 7 | X27: 3.31 | Y27: =IF(X27<=2,"Stage 0",IF(X27<=4,"Stage I",IF(X27<=6,"Stage II",IF(X27<=8,"Stage III", "Stage IV")))) -> Stage I | Z27: =IF(U27<>"",U27,ROUND(AVERAGEIF(S27:S557,S27,U27:U557),2)) -> 60800.41
A28: PT0010978 | B28: 50 | C28: Male | D28: =PROPER(Table3[[#This Row],[Gender]]) -> Male | E28: Australia | F28: =PROPER(Table3[[#This Row],[Country_Region]]) -> Australia | G28: 2024 | H28: 9.2 | I28: =IF(H28="", AVERAGEIF('CLEANED DATASET'!$G$2:$G$532,G28,'CLEANED DATASET'!$H467),H28) -> 9.2 | J28: 8.2 | K28: =IF(J28="",ROUND(AVERAGEIF(G32:G558,G28,J28:J558),1),J28) -> 8.2 | L28: 4.5 | M28: =IF(L28="", AVERAGEIF(G28:G558, G28,L28:L558),L28) -> 4.5 | N28: 0.8 | O28: =IF(N28="",AVERAGEIF(G28:G558,G28,N28:N558),N28) -> 0.8 | P28: 8.8 | Q28: =IF(P28="",AVERAGEIF(G28:G558,G28,P28:P558),P28) -> 8.8 | R28: Lung | S28: =PROPER(Table3[[#This Row],[Cancer_Type]]) -> Lung | T28: Stage I | U28: 46714.31 | V28: 2.6 | W28: =IF(Y28="Stage 0",RANDBETWEEN(9,10), IF(Y28="Stage I",RANDBETWEEN(7,8), IF(Y28="Stage II",RANDBETWEEN(5,6), IF(Y28="Stage III",RANDBETWEEN(3,4), IF(Y28="Stage IV",RANDBETWEEN(1,2),""))))) -> 6 | X28: 5.85 | Y28: =IF(X28<=2,"Stage 0",IF(X28<=4,"Stage I",IF(X28<=6,"Stage II",IF(X28<=8,"Stage III", "Stage IV")))) -> Stage II | Z28: =IF(U28<>"",U28,ROUND(AVERAGEIF(S28:S558,S28,U28:U558),2)) -> 46714.31
A29: PT0011075 | B29: 42 | C29: Male | D29: =PROPER(Table3[[#This Row],[Gender]]) -> Male | E29: Canada | F29: =PROPER(Table3[[#This Row],[Country_Region]]) -> Canada | G29: 2024 | H29: 1 | I29: =IF(H29="", AVERAGEIF('CLEANED DATASET'!$G$2:$G$532,G29,'CLEANED DATASET'!$H132),H29) -> 1 | J29: 8.2 | K29: =IF(J29="",ROUND(AVERAGEIF(G33:G559,G29,J29:J559),1),J29) -> 8.2 | L29: 0.4 | M29: =IF(L29="", AVERAGEIF(G29:G559, G29,L29:L559),L29) -> 0.4 | N29: 8.9 | O29: =IF(N29="",AVERAGEIF(G29:G559,G29,N29:N559),N29) -> 8.9 | P29: 0.6 | Q29: =IF(P29="",AVERAGEIF(G29:G559,G29,P29:P559),P29) -> 0.6 | R29: Liver | S29: =PROPER(Table3[[#This Row],[Cancer_Type]]) -> Liver | T29: Stage I | U29: 93205.45 | V29: 5.7 | W29: =IF(Y29="Stage 0",RANDBETWEEN(9,10), IF(Y29="Stage I",RANDBETWEEN(7,8), IF(Y29="Stage II",RANDBETWEEN(5,6), IF(Y29="Stage III",RANDBETWEEN(3,4), IF(Y29="Stage IV",RANDBETWEEN(1,2),""))))) -> 2 | X29: =ROUND(I29+K29+M29+O29+Q29+(10-V29)/6, 2) -> 19.82 | Y29: =IF(X29<=2,"Stage 0",IF(X29<=4,"Stage I",IF(X29<=6,"Stage II",IF(X29<=8,"Stage III", "Stage IV")))) -> Stage IV | Z29: =IF(U29<>"",U29,ROUND(AVERAGEIF(S29:S559,S29,U29:U559),2)) -> 93205.45
A30: PT0011111 | B30: 50 | C30: Male | D30: =PROPER(Table3[[#This Row],[Gender]]) -> Male | E30: RUSSIA | F30: =PROPER(Table3[[#This Row],[Country_Region]]) -> Russia | G30: 2024 | H30: 0.9 | I30: =IF(H30="", AVERAGEIF('CLEANED DATASET'!$G$2:$G$532,G30,'CLEANED DATASET'!$H351),H30) -> 0.9 | J30: 1.2 | K30: =IF(J30="",ROUND(AVERAGEIF(G34:G560,G30,J30:J560),1),J30) -> 1.2 | L30: 4.5 | M30: =IF(L30="", AVERAGEIF(G30:G560, G30,L30:L560),L30) -> 4.5 | N30: 7.3 | O30: =IF(N30="",AVERAGEIF(G30:G560,G30,N30:N560),N30) -> 7.3 | P30: 1 | Q30: =IF(P30="",AVERAGEIF(G30:G560,G30,P30:P560),P30) -> 1 | R30: Lung | S30: =PROPER(Table3[[#This Row],[Cancer_Type]]) -> Lung | T30: Stage 0 | U30: 8993.81 | V30: 3.3 | W30: =IF(Y30="Stage 0",RANDBETWEEN(9,10), IF(Y30="Stage I",RANDBETWEEN(7,8), IF(Y30="Stage II",RANDBETWEEN(5,6), IF(Y30="Stage III",RANDBETWEEN(3,4), IF(Y30="Stage IV",RANDBETWEEN(1,2),""))))) -> 5 | X30: 4.42 | Y30: =IF(X30<=2,"Stage 0",IF(X30<=4,"Stage I",IF(X30<=6,"Stage II",IF(X30<=8,"Stage III", "Stage IV")))) -> Stage II | Z30: =IF(U30<>"",U30,ROUND(AVERAGEIF(S30:S560,S30,U30:U560),2)) -> 8993.81
A31: PT0011287 | B31: 30 | C31: Other | D31: =PROPER(Table3[[#This Row],[Gender]]) -> Other | E31: Russia | F31: =PROPER(Table3[[#This Row],[Country_Region]]) -> Russia | G31: 2024 | H31: 6.3 | I31: =IF(H31="", AVERAGEIF('CLEANED DATASET'!$G$2:$G$532,G31,'CLEANED DATASET'!$H140),H31) -> 6.3 | J31: 8 | K31: =IF(J31="",ROUND(AVERAGEIF(G35:G561,G31,J31:J561),1),J31) -> 8 | L31: 7.6 | M31: =IF(L31="", AVERAGEIF(G31:G561, G31,L31:L561),L31) -> 7.6 | N31: 6.2 | O31: =IF(N31="",AVERAGEIF(G31:G561,G31,N31:N561),N31) -> 6.2 | P31: 2.5 | Q31: =IF(P31="",AVERAGEIF(G31:G561,G31,P31:P561),P31) -> 2.5 | R31: Colon | S31: =PROPER(Table3[[#This Row],[Cancer_Type]]) -> Colon | T31: Stage I | U31: 23062.07 | V31: 1.8 | W31: =IF(Y31="Stage 0",RANDBETWEEN(9,10), IF(Y31="Stage I",RANDBETWEEN(7,8), IF(Y31="Stage II",RANDBETWEEN(5,6), IF(Y31="Stage III",RANDBETWEEN(3,4), IF(Y31="Stage IV",RANDBETWEEN(1,2),""))))) -> 4 | X31: 6.63 | Y31: =IF(X31<=2,"Stage 0",IF(X31<=4,"Stage I",IF(X31<=6,"Stage II",IF(X31<=8,"Stage III", "Stage IV")))) -> Stage III | Z31: =IF(U31<>"",U31,ROUND(AVERAGEIF(S31:S561,S31,U31:U561),2)) -> 23062.07
A32: PT0011480 | B32: 67 | C32: Male | D32: =PROPER(Table3[[#This Row],[Gender]]) -> Male | E32: Brazil | F32: =PROPER(Table3[[#This Row],[Country_Region]]) -> Brazil | G32: 2024 | H32: 5.7 | I32: =IF(H32="", AVERAGEIF('CLEANED DATASET'!$G$2:$G$532,G32,'CLEANED DATASET'!$H237),H32) -> 5.7 | K32: =IF(J32="",ROUND(AVERAGEIF(G36:G562,G32,J32:J562),1),J32) -> 4.8 | L32: 7.4 | M32: =IF(L32="", AVERAGEIF(G32:G562, G32,L32:L562),L32) -> 7.4 | N32: 2.2 | O32: =IF(N32="",AVERAGEIF(G32:G562,G32,N32:N562),N32) -> 2.2 | P32: 7 | Q32: =IF(P32="",AVERAGEIF(G32:G562,G32,P32:P562),P32) -> 7 | R32: Leukemia | S32: =PROPER(Table3[[#This Row],[Cancer_Type]]) -> Leukemia | T32: Stage II | U32: 13404.04 | V32: 6.1 | W32: =IF(Y32="Stage 0",RANDBETWEEN(9,10), IF(Y32="Stage I",RANDBETWEEN(7,8), IF(Y32="Stage II",RANDBETWEEN(5,6), IF(Y32="Stage III",RANDBETWEEN(3,4), IF(Y32="Stage IV",RANDBETWEEN(1,2),""))))) -> 4 | X32: 6.07 | Y32: =IF(X32<=2,"Stage 0",IF(X32<=4,"Stage I",IF(X32<=6,"Stage II",IF(X32<=8,"Stage III", "Stage IV")))) -> Stage III | Z32: =IF(U32<>"",U32,ROUND(AVERAGEIF(S32:S562,S32,U32:U562),2)) -> 13404.04
A33: PT0011508 | B33: 74 | C33: Other | D33: =PROPER(Table3[[#This Row],[Gender]]) -> Other | E33: Germany | F33: =PROPER(Table3[[#This Row],[Country_Region]]) -> Germany | G33: 2024 | H33: 6.3 | I33: =IF(H33="", AVERAGEIF('CLEANED DATASET'!$G$2:$G$532,G33,'CLEANED DATASET'!$H339),H33) -> 6.3 | J33: 4.8 | K33: =IF(J33="",ROUND(AVERAGEIF(G37:G563,G33,J33:J563),1),J33) -> 4.8 | L33: 4.9 | M33: =IF(L33="", AVERAGEIF(G33:G563, G33,L33:L563),L33) -> 4.9 | N33: 9.1 | O33: =IF(N33="",AVERAGEIF(G33:G563,G33,N33:N563),N33) -> 9.1 | P33: 1.2 | Q33: =IF(P33="",AVERAGEIF(G33:G563,G33,P33:P563),P33) -> 1.2 | R33: Leukemia | S33: =PROPER(Table3[[#This Row],[Cancer_Type]]) -> Leukemia | T33: Stage III | U33: 65768.34 | V33: 7.4 | W33: =IF(Y33="Stage 0",RANDBETWEEN(9,10), IF(Y33="Stage I",RANDBETWEEN(7,8), IF(Y33="Stage II",RANDBETWEEN(5,6), IF(Y33="Stage III",RANDBETWEEN(3,4), IF(Y33="Stage IV",RANDBETWEEN(1,2),""))))) -> 6 | X33: 5.34 | Y33: =IF(X33<=2,"Stage 0",IF(X33<=4,"Stage I",IF(X33<=6,"Stage II",IF(X33<=8,"Stage III", "Stage IV")))) -> Stage II | Z33: =IF(U33<>"",U33,ROUND(AVERAGEIF(S33:S563,S33,U33:U563),2)) -> 65768.34
A34: PT0011527 | B34: 59 | C34: Male | D34: =PROPER(Table3[[#This Row],[Gender]]) -> Male | E34: India | F34: =PROPER(Table3[[#This Row],[Country_Region]]) -> India | G34: 2023 | H34: 1.7 | I34: =IF(H34="", AVERAGEIF('CLEANED DATASET'!$G$2:$G$532,G34,'CLEANED DATASET'!$H498),H34) -> 1.7 | J34: 5.3 | K34: =IF(J34="",ROUND(AVERAGEIF(G38:G564,G34,J34:J564),1),J34) -> 5.3 | L34: 3.9 | M34: =IF(L34="", AVERAGEIF(G34:G564, G34,L34:L564),L34) -> 3.9 | N34: 3 | O34: =IF(N34="",AVERAGEIF(G34:G564,G34,N34:N564),N34) -> 3 | P34: 5.2 | Q34: =IF(P34="",AVERAGEIF(G34:G564,G34,P34:P564),P34) -> 5.2 | R34: Cervical | S34: =PROPER(Table3[[#This Row],[Cancer_Type]]) -> Cervical | U34: 69969.01 | V34: 4.6 | W34: =IF(Y34="Stage 0",RANDBETWEEN(9,10), IF(Y34="Stage I",RANDBETWEEN(7,8), IF(Y34="Stage II",RANDBETWEEN(5,6), IF(Y34="Stage III",RANDBETWEEN(3,4), IF(Y34="Stage IV",RANDBETWEEN(1,2),""))))) -> 8 | X34: 3.44 | Y34: =IF(X34<=2,"Stage 0",IF(X34<=4,"Stage I",IF(X34<=6,"Stage II",IF(X34<=8,"Stage III", "Stage IV")))) -> Stage I | Z34: =IF(U34<>"",U34,ROUND(AVERAGEIF(S34:S564,S34,U34:U564),2)) -> 69969.01
A35: PT0011735 | B35: 33 | C35: Female | D35: =PROPER(Table3[[#This Row],[Gender]]) -> Female | E35: UK | F35: =PROPER(Table3[[#This Row],[Country_Region]]) -> Uk | G35: 2024 | H35: 4.8 | I35: =IF(H35="", AVERAGEIF('CLEANED DATASET'!$G$2:$G$532,G35,'CLEANED DATASET'!$H428),H35) -> 4.8 | J35: 9.6 | K35: =IF(J35="",ROUND(AVERAGEIF(G39:G565,G35,J35:J565),1),J35) -> 9.6 | L35: 3 | M35: =IF(L35="", AVERAGEIF(G35:G565, G35,L35:L565),L35) -> 3 | N35: 2.3 | O35: =IF(N35="",AVERAGEIF(G35:G565,G35,N35:N565),N35) -> 2.3 | Q35: =IF(P35="",AVERAGEIF(G35:G565,G35,P35:P565),P35) -> 4.2398649 | R35: Lung | S35: =PROPER(Table3[[#This Row],[Cancer_Type]]) -> Lung | T35: Stage I | U35: 93182.85 | V35: 8.1 | W35: =IF(Y35="Stage 0",RANDBETWEEN(9,10), IF(Y35="Stage I",RANDBETWEEN(7,8), IF(Y35="Stage II",RANDBETWEEN(5,6), IF(Y35="Stage III",RANDBETWEEN(3,4), IF(Y35="Stage IV",RANDBETWEEN(1,2),""))))) -> 6 | X35: 4.17 | Y35: =IF(X35<=2,"Stage 0",IF(X35<=4,"Stage I",IF(X35<=6,"Stage II",IF(X35<=8,"Stage III", "Stage IV")))) -> Stage II | Z35: =IF(U35<>"",U35,ROUND(AVERAGEIF(S35:S565,S35,U35:U565),2)) -> 93182.85
A36: PT0011794 | B36: 24 | C36: Other | D36: =PROPER(Table3[[#This Row],[Gender]]) -> Other | E36: China | F36: =PROPER(Table3[[#This Row],[Country_Region]]) -> China | G36: 2023 | H36: 6.6 | I36: =IF(H36="", AVERAGEIF('CLEANED DATASET'!$G$2:$G$532,G36,'CLEANED DATASET'!$H496),H36) -> 6.6 | J36: 2 | K36: =IF(J36="",ROUND(AVERAGEIF(G40:G566,G36,J36:J566),1),J36) -> 2 | L36: 5.8 | M36: =IF(L36="", AVERAGEIF(G36:G566, G36,L36:L566),L36) -> 5.8 | N36: 5.3 | O36: =IF(N36="",AVERAGEIF(G36:G566,G36,N36:N566),N36) -> 5.3 | P36: 0.6 | Q36: =IF(P36="",AVERAGEIF(G36:G566,G36,P36:P566),P36) -> 0.6 | R36: Breast | S36: =PROPER(Table3[[#This Row],[Cancer_Type]]) -> Breast | T36: Stage II | U36: 41115.23 | V36: 4.3 | W36: =IF(Y36="Stage 0",RANDBETWEEN(9,10), IF(Y36="Stage I",RANDBETWEEN(7,8), IF(Y36="Stage II",RANDBETWEEN(5,6), IF(Y36="Stage III",RANDBETWEEN(3,4), IF(Y36="Stage IV",RANDBETWEEN(1,2),""))))) -> 5 | X36: 4.79 | Y36: =IF(X36<=2,"Stage 0",IF(X36<=4,"Stage I",IF(X36<=6,"Stage II",IF(X36<=8,"Stage III", "Stage IV")))) -> Stage II | Z36: =IF(U36<>"",U36,ROUND(AVERAGEIF(S36:S566,S36,U36:U566),2)) -> 41115.23
A37: PT0011817 | B37: 41 | C37: Male | D37: =PROPER(Table3[[#This Row],[Gender]]) -> Male | E37: Germany | F37: =PROPER(Table3[[#This Row],[Country_Region]]) -> Germany | G37: 2022 | H37: 1.9 | I37: =IF(H37="", AVERAGEIF('CLEANED DATASET'!$G$2:$G$532,G37,'CLEANED DATASET'!$H397),H37) -> 1.9 | J37: 3.2 | K37: =IF(J37="",ROUND(AVERAGEIF(G41:G567,G37,J37:J567),1),J37) -> 3.2 | L37: 6.9 | M37: =IF(L37="", AVERAGEIF(G37:G567, G37,L37:L567),L37) -> 6.9 | N37: 8.9 | O37: =IF(N37="",AVERAGEIF(G37:G567,G37,N37:N567),N37) -> 8.9 | P37: 6 | Q37: =IF(P37="",AVERAGEIF(G37:G567,G37,P37:P567),P37) -> 6 | R37: Colon | S37: =PROPER(Table3[[#This Row],[Cancer_Type]]) -> Colon | T37: Stage 0 | U37: 29291.96 | V37: 3.2 | W37: =IF(Y37="Stage 0",RANDBETWEEN(9,10), IF(Y37="Stage I",RANDBETWEEN(7,8), IF(Y37="Stage II",RANDBETWEEN(5,6), IF(Y37="Stage III",RANDBETWEEN(3,4), IF(Y37="Stage IV",RANDBETWEEN(1,2),""))))) -> 5 | X37: 5.69 | Y37: =IF(X37<=2,"Stage 0",IF(X37<=4,"Stage I",IF(X37<=6,"Stage II",IF(X37<=8,"Stage III", "Stage IV")))) -> Stage II | Z37: =IF(U37<>"",U37,ROUND(AVERAGEIF(S37:S567,S37,U37:U567),2)) -> 29291.96
A38: PT0011848 | B38: 54 | C38: Male | D38: =PROPER(Table3[[#This Row],[Gender]]) -> Male | E38: CHINA | F38: =PROPER(Table3[[#This Row],[Country_Region]]) -> China | G38: 2024 | H38: 5 | I38: =IF(H38="", AVERAGEIF('CLEANED DATASET'!$G$2:$G$532,G38,'CLEANED DATASET'!$H103),H38) -> 5 | J38: 0.8 | K38: =IF(J38="",ROUND(AVERAGEIF(G42:G568,G38,J38:J568),1),J38) -> 0.8 | L38: 7.7 | M38: =IF(L38="", AVERAGEIF(G38:G568, G38,L38:L568),L38) -> 7.7 | N38: 3.4 | O38: =IF(N38="",AVERAGEIF(G38:G568,G38,N38:N568),N38) -> 3.4 | P38: 4 | Q38: =IF(P38="",AVERAGEIF(G38:G568,G38,P38:P568),P38) -> 4 | R38: Cervical | S38: =PROPER(Table3[[#This Row],[Cancer_Type]]) -> Cervical | T38: Stage 0 | U38: 32778.75 | V38: 4.7 | W38: =IF(Y38="Stage 0",RANDBETWEEN(9,10), IF(Y38="Stage I",RANDBETWEEN(7,8), IF(Y38="Stage II",RANDBETWEEN(5,6), IF(Y38="Stage III",RANDBETWEEN(3,4), IF(Y38="Stage IV",RANDBETWEEN(1,2),""))))) -> 6 | X38: 4.7 | Y38: =IF(X38<=2,"Stage 0",IF(X38<=4,"Stage I",IF(X38<=6,"Stage II",IF(X38<=8,"Stage III", "Stage IV")))) -> Stage II | Z38: =IF(U38<>"",U38,ROUND(AVERAGEIF(S38:S568,S38,U38:U568),2)) -> 32778.75
A39: PT0011915 | B39: 69 | C39: Other | D39: =PROPER(Table3[[#This Row],[Gender]]) -> Other | E39: Germany | F39: =PROPER(Table3[[#This Row],[Country_Region]]) -> Germany | G39: 2022 | H39: 0.2 | I39: =IF(H39="", AVERAGEIF('CLEANED DATASET'!$G$2:$G$532,G39,'CLEANED DATASET'!$H312),H39) -> 0.2 | J39: 2.9 | K39: =IF(J39="",ROUND(AVERAGEIF(G43:G569,G39,J39:J569),1),J39) -> 2.9 | L39: 9.8 | M39: =IF(L39="", AVERAGEIF(G39:G569, G39,L39:L569),L39) -> 9.8 | N39: 0.6 | O39: =IF(N39="",AVERAGEIF(G39:G569,G39,N39:N569),N39) -> 0.6 | P39: 2.9 | Q39: =IF(P39="",AVERAGEIF(G39:G569,G39,P39:P569),P39) -> 2.9 | R39: Colon | S39: =PROPER(Table3[[#This Row],[Cancer_Type]]) -> Colon | T39: Stage I | U39: 78214.32 | V39: 4.5 | W39: =IF(Y39="Stage 0",RANDBETWEEN(9,10), IF(Y39="Stage I",RANDBETWEEN(7,8), IF(Y39="Stage II",RANDBETWEEN(5,6), IF(Y39="Stage III",RANDBETWEEN(3,4), IF(Y39="Stage IV",RANDBETWEEN(1,2),""))))) -> 7 | X39: 2.79 | Y39: =IF(X39<=2,"Stage 0",IF(X39<=4,"Stage I",IF(X39<=6,"Stage II",IF(X39<=8,"Stage III", "Stage IV")))) -> Stage I | Z39: =IF(U39<>"",U39,ROUND(AVERAGEIF(S39:S569,S39,U39:U569),2)) -> 78214.32
A40: PT0011946 | B40: 60 | C40: Male | D40: =PROPER(Table3[[#This Row],[Gender]]) -> Male | E40: UK | F40: =PROPER(Table3[[#This Row],[Country_Region]]) -> Uk | G40: 2024 | H40: 8.7 | I40: =IF(H40="", AVERAGEIF('CLEANED DATASET'!$G$2:$G$532,G40,'CLEANED DATASET'!$H147),H40) -> 8.7 | J40: 5.4 | K40: =IF(J40="",ROUND(AVERAGEIF(G44:G570,G40,J40:J570),1),J40) -> 5.4 | L40: 0.2 | M40: =IF(L40="", AVERAGEIF(G40:G570, G40,L40:L570),L40) -> 0.2 | N40: 2.2 | O40: =IF(N40="",AVERAGEIF(G40:G570,G40,N40:N570),N40) -> 2.2 | P40: 1.7 | Q40: =IF(P40="",AVERAGEIF(G40:G570,G40,P40:P570),P40) -> 1.7 | R40: Cervical | S40: =PROPER(Table3[[#This Row],[Cancer_Type]]) -> Cervical | T40: Stage 0 | V40: 9.6 | W40: =IF(Y40="Stage 0",RANDBETWEEN(9,10), IF(Y40="Stage I",RANDBETWEEN(7,8), IF(Y40="Stage II",RANDBETWEEN(5,6), IF(Y40="Stage III",RANDBETWEEN(3,4), IF(Y40="Stage IV",RANDBETWEEN(1,2),""))))) -> 5 | X40: 4.09 | Y40: =IF(X40<=2,"Stage 0",IF(X40<=4,"Stage I",IF(X40<=6,"Stage II",IF(X40<=8,"Stage III", "Stage IV")))) -> Stage II | Z40: =IF(U40<>"",U40,ROUND(AVERAGEIF(S40:S570,S40,U40:U570),2)) -> 49539.28
...

Sheet PIVOT TABLE
A1: 1. CANCER TYPE WISE PATIENT COUNT | D1: 2. YEAR WISE TREATMENT COST-AVERAGE | G1: 3. CANCER STAGE WISE SURVIVAL YEARS-AVERAGE
A2: Row Labels | B2: Count of Patient_ID | D2: Row Labels | E2: Average of Treatment_Cost_USD | G2: Row Labels | H2: Average of Survival_Year
A3: Breast | B3: 65 | D3: 2022 | E3: 52797.118 | G3: Stage 0 | H3: 2.2
A4: Cervical | B4: 68 | D4: 2023 | E4: 50580.43 | G4: Stage I | H4: 5.1635593
A5: Colon | B5: 64 | D5: 2024 | E5: 51751.069 | G5: Stage II | H5: 5.2364821
A6: Leukemia | B6: 60 | D6: Grand Total | E6: 51711.04 | G6: Stage III | H6: 5.4123457
A7: Liver | B7: 62 | G7: Stage IV | H7: 4.975
A8: Lung | B8: 58 | G8: Grand Total | H8: 5.2295669
A9: Prostate | B9: 60 | D9: 4. COUNTRY-WISE PATIENT COUNT
A10: Skin | B10: 64 | D10: Row Labels | E10: Count of Patient_ID | G10: 5. GENDER WISE CANCER TYPE DISTRIBUTION
A11: Unknown | B11: 30 | D11: Australia | E11: 61 | G11: Count of Patient_ID | H11: Column Labels
A12: Grand Total | B12: 531 | D12: Brazil | E12: 54 | G12: Row Labels | H12: Female | I12: Male | J12: Other | K12: Unknown | L12: Grand Total
D13: Canada | E13: 50 | G13: Breast | H13: 23 | I13: 21 | J13: 18 | K13: 3 | L13: 65
A14: 6.CANCER TYPE WISE AVERAGE TREATMENT COST | D14: China | E14: 52 | G14: Cervical | H14: 19 | I14: 24 | J14: 21 | K14: 4 | L14: 68
A15: Row Labels | B15: Average of Treatment_Cost_USD | D15: Germany | E15: 64 | G15: Colon | H15: 17 | I15: 24 | J15: 21 | K15: 2 | L15: 64
A16: Breast | B16: 48055.013 | D16: India | E16: 52 | G16: Leukemia | H16: 17 | I16: 21 | J16: 16 | K16: 6 | L16: 60
A17: Cervical | B17: 49123.956 | D17: Pakistan | E17: 53 | G17: Liver | H17: 19 | I17: 22 | J17: 18 | K17: 3 | L17: 62
A18: Colon | B18: 57014.704 | D18: Russia | E18: 57 | G18: Lung | H18: 17 | I18: 18 | J18: 18 | K18: 5 | L18: 58
A19: Leukemia | B19: 52577.286 | D19: UK | E19: 56 | G19: Prostate | H19: 19 | I19: 19 | J19: 15 | K19: 7 | L19: 60
A20: Liver | B20: 53418.353 | D20: USA | E20: 32 | G20: Skin | H20: 21 | I20: 21 | J20: 19 | K20: 3 | L20: 64
A21: Lung | B21: 50661.775 | D21: Grand Total | E21: 531 | G21: Unknown | H21: 8 | I21: 7 | J21: 8 | K21: 7 | L21: 30
A22: Prostate | B22: 54133.743 | G22: Grand Total | H22: 160 | I22: 177 | J22: 154 | K22: 40 | L22: 531
A23: Skin | B23: 49666.545
A24: Unknown | B24: 50465.825
A25: Grand Total | B25: 51711.04

Sheet CLEANED FINAL
A1: PATIENT_ID | B1: AGE | C1: GENDER | D1: COUNTRY REGION | E1: YEAR | F1: GENETIC_RISK | G1: AIR POLLUTION | H1: ALCOHOL USE | I1: SMOKING | J1: OBESITY LEVEL | K1: CANCER_TYPE | L1: SURVIVAL YEAR | M1: TARGET_SEVERITY_SCORE | N1: CANCER STAGE | O1: TREATMENT COST USD
A2: PT0001777 | B2: 60 | C2: Male | D2: Australia | E2: 2022 | F2: 6.1 | G2: 2.1 | H2: 6.3 | I2: 4.6005848 | J2: 0.6 | K2: Breast | L2: 7 | M2: 3.93 | N2: Stage I | O2: 35502.54
A3: PT0006143 | B3: 70 | C3: Male | D3: Russia | E3: 2023 | F3: 1.6 | G3: 2 | H3: 4.3 | I3: 5 | J3: 0.8 | K3: Leukemia | L3: 6 | M3: 4.02 | N3: Stage II | O3: 16273.05
A4: PT0006792 | B4: 33 | C4: Other | D4: Brazil | E4: 2024 | F4: 9.1 | G4: 7.5 | H4: 4.712963 | I4: 7.5 | J4: 7 | K4: Colon | L4: 4 | M4: 7.14 | N4: Stage III | O4: 22899.65
A5: PT0007169 | B5: 87 | C5: Female | D5: Russia | E5: 2022 | F5: 7.5 | G5: 8.5 | H5: 0.9 | I5: 2.7 | J5: 8 | K5: Skin | L5: 4 | M5: 6.05 | N5: Stage III | O5: 10195.07
A6: PT0007406 | B6: 56 | C6: Male | D6: China | E6: 2022 | F6: 5.2 | G6: 3.7 | H6: 4.4 | I6: 3.8 | J6: 8.1 | K6: Cervical | L6: 6 | M6: 5.66 | N6: Stage II | O6: 8481.64
A7: PT0008067 | B7: 51 | C7: Male | D7: Pakistan | E7: 2024 | F7: 0.6 | G7: 9.7 | H7: 0.8 | I7: 5.0527607 | J7: 4.2546584 | K7: Leukemia | L7: 8 | M7: 3.16 | N7: Stage I | O7: 76197.01
A8: PT0008765 | B8: 29 | C8: Female | D8: Pakistan | E8: 2022 | F8: 1 | G8: 9.2 | H8: 3.7 | I8: 3.4 | J8: 2.5 | K8: Cervical | L8: 6 | M8: 4.5 | N8: Stage II | O8: 51711.04
A9: PT0008770 | B9: 73 | C9: Other | D9: Brazil | E9: 2023 | F9: 8.5 | G9: 5.7 | H9: 0.6 | I9: 4.3 | J9: 2.9 | K9: Liver | L9: 5 | M9: 4.58 | N9: Stage II | O9: 60883.56
A10: PT0008867 | B10: 29 | C10: Unknown | D10: Canada | E10: 2024 | F10: 4.0736842 | G10: 3.5 | H10: 7.1 | I10: 2.2 | J10: 3.6 | K10: Prostate | L10: 7 | M10: 3.3 | N10: Stage I | O10: 94485.75
A11: PT0009237 | B11: 33 | C11: Female | D11: Pakistan | E11: 2023 | F11: 7.7 | G11: 4.5 | H11: 2.4 | I11: 2.3 | J11: 5.2 | K11: Colon | L11: 6 | M11: 4.69 | N11: Stage II | O11: 43439
A12: PT0009519 | B12: 23 | C12: Other | D12: India | E12: 2024 | F12: 1.6 | G12: 0.5 | H12: 3.5 | I12: 4.6 | J12: 7.8 | K12: Leukemia | L12: 8 | M12: 3.3 | N12: Stage I | O12: 66140.43
A13: PT0009578 | B13: 47 | C13: Male | D13: Usa | E13: 2024 | F13: 7.7 | G13: 0.9 | H13: 3 | I13: 6.5 | J13: 5.9 | K13: Leukemia | L13: 5 | M13: 4.98 | N13: Stage II | O13: 51804.21
... A532: PT0049770 | B532: 67 | C532: Female | D532: Australia | E532: 2022 | F532: 1.6 | G532: 5.6 | H532: 4.7 | I532: 3.3 | J532: 4.9 | K532: Skin | L532: 8 | M532: 3.14 | N532: Stage I | O532: 93848.98
